<?xml version="1.0"?>
<robot xmlns:xacro="http://www.ros.org/wiki/xacro" name="rover">

<xacro:include filename="camera.xacro" />

<link name="base_footprint"/>

<link name="base_link">
    <inertial>
        <origin xyz="0.0 0.0 0.0" rpy="0.0 0.0 0.0"/>
        <mass value="1.0"/>
        <inertia ixx="0.4" ixy="0.0" ixz="0.0"
                 iyy="0.4" iyz="0.0"
                 izz="0.2"/>
    </inertial>
    <visual name="">
        <origin xyz="0.0 0.0 0.1" rpy="0.0 0.0 0.0"/>
        <geometry>
            <box size="0.8 0.32 0.3"/>
        </geometry>
        <material name="">
            <color rgba="1.0 0.0 0.0 1.0"/>
            <texture filename=""/>
        </material>
    </visual>
    <collision>
        <origin xyz="0.0 0.0 0.0" rpy="0.0 0.0 0.0"/>
        <geometry>
            <box size="0.0 0.0 0.0"/>
        </geometry>
    </collision>
</link>

<joint name="base_joint" type="fixed">
    <origin xyz="0.0 0.0 0.135" rpy="0.0 0.0 0.0"/>
    <parent link="base_footprint"/>
    <child link="base_link"/>
    <axis xyz="0.0 0.0 0.0"/>
</joint>

<!-- All Wheel links and joints -->


<xacro:macro name="wheel" params="name x y">

    <link name="wheel_${name}_link">
        <inertial>
            <origin xyz="0.0 0.0 0.0" rpy="0.0 0.0 0.0"/>
            <mass value="0.5"/>
            <inertia ixx="0.0" ixy="0.0" ixz="0.0" iyy="0.0" iyz="0.0" izz="0.0"/>
        </inertial>
        <visual name="">
            <origin xyz="0.0 0.0 0.0" rpy="0.0 0.0 0.0"/>
            <geometry>
                <mesh filename="package://mobile_robot/meshes/left_tire.stl" scale="0.005 0.005 0.005"/>
            </geometry>
            <material name="black">
                <color rgba=".0 .0 0.0 1.0"/>
            </material>
        </visual>
        <collision>
            <origin xyz="0.0 0.0 0.0" rpy="0.0 0.0 0.0"/>
            <geometry>
                <mesh filename="package://mobile_robot/meshes/left_tire.stl" scale="0.005 0.005 0.005"/>
            </geometry>
        </collision>
    </link>

    <joint name="wheel_${name}_joint" type="continuous">
        <origin xyz="${x} ${y} .0" rpy="0 0.0 0.0"/>
        <parent link="base_link"/>
        <child link="wheel_${name}_link"/>
        <axis xyz=".0 1.0 .0"/>

    <transmission name="wheel_${name}_trans">
      <type>transmission_interface/SimpleTransmission</type>
      <actuator name="${name}_motor" />
      <joint name="wheel_${name}_joint" />
      <mechanicalReduction>1</mechanicalReduction>
    </transmission>        
        
    </joint>

</xacro:macro>


  <gazebo>
    <plugin name="gazebo_ros_control" filename="libgazebo_ros_control.so">
      <robotNamespace>/rover</robotNamespace>
    </plugin>
    <plugin name="gazebo_ros_diff_drive" filename="libgazebo_ros_diff_drive.so">
      <alwaysOn>true</alwaysOn>
      <updateRate>100</updateRate>
      <leftJoint>front_left_wheel_joint</leftJoint>
      <rightJoint>front_right_wheel_joint</rightJoint>
      <wheelSeparation>0.5</wheelSeparation>
      <wheelDiameter>0.1</wheelDiameter>
      <torque>5.0</torque>
      <commandTopic>cmd_vel</commandTopic>
      <odometryTopic>odom</odometryTopic>
      <odometryFrame>odom</odometryFrame>
      <robotBaseFrame>base_link</robotBaseFrame>
      <robotNamespace>/rover</robotNamespace>
      
      <rosDebugLevel>1</rosDebugLevel>
      <publishWheelTF>true</publishWheelTF>
      <publishOdomTF>true</publishOdomTF>
      <publishWheelJointState>true</publishWheelJointState>
      <wheelAcceleration>5.0</wheelAcceleration>
      <wheelTorque>50.0</wheelTorque>
      <odometrySource>1</odometrySource>      
      
    </plugin>
  </gazebo>


<!-- Wheel Creating using macros -->
<xacro:wheel name="rear_right"  x="0.275" y =" 0.20"/>
<xacro:wheel name="front_right" x="-0.275" y =" 0.20"/>
<xacro:wheel name="front_left"  x="-0.275" y =" -0.20"/>
<xacro:wheel name="rear_left"   x="0.275" y =" -0.20"/>




</robot>
